<ns0:test-suite xmlns:ns0="urn:model.allure.qatools.yandex.ru" start="1578641247880" stop="1578641247880">
  <description>This is the tests collection phase. Failures are modules that failed to collect.</description>
  <name>test_collection_phase</name>
  <title>Collection phase</title>
  <labels/>
  <test-cases>
    <test-case start="1578641247880" status="broken" stop="1578641247880">
      <name>test02_mp_article</name>
      <failure>
        <message>failed</message>
        <stack-trace>..\..\..\AppData\Local\Programs\Python\Python36-32\lib\site-packages\py\_path\local.py:701: in pyimport
    __import__(modname)
&lt;frozen importlib._bootstrap&gt;:971: in _find_and_load
    ???
&lt;frozen importlib._bootstrap&gt;:955: in _find_and_load_unlocked
    ???
&lt;frozen importlib._bootstrap&gt;:656: in _load_unlocked
    ???
&lt;frozen importlib._bootstrap&gt;:626: in _load_backward_compatible
    ???
..\..\..\AppData\Local\Programs\Python\Python36-32\lib\site-packages\_pytest\assertion\rewrite.py:296: in load_module
    six.exec_(co, mod.__dict__)
F:\PythonItem\hmtq\bj17\UiHMTTAutoItem\scripts\test02_mp_article.py:2: in &lt;module&gt;
    ???
..\page\page_in.py:1: in &lt;module&gt;
    from page.page_mis_audit import PageMisAudit
..\page\page_mis_audit.py:3: in &lt;module&gt;
    from base.web_base import WabDriver
..\base\web_base.py:5: in &lt;module&gt;
    from base.base import Base
..\base\base.py:7: in &lt;module&gt;
    log = GetLog.get_logger()
..\tools\get_log.py:17: in get_logger
    encoding="utf-8")
..\..\..\AppData\Local\Programs\Python\Python36-32\lib\logging\handlers.py:202: in __init__
    BaseRotatingHandler.__init__(self, filename, 'a', encoding, delay)
..\..\..\AppData\Local\Programs\Python\Python36-32\lib\logging\handlers.py:57: in __init__
    logging.FileHandler.__init__(self, filename, mode, encoding, delay)
..\..\..\AppData\Local\Programs\Python\Python36-32\lib\logging\__init__.py:1030: in __init__
    StreamHandler.__init__(self, self._open())
..\..\..\AppData\Local\Programs\Python\Python36-32\lib\logging\__init__.py:1059: in _open
    return open(self.baseFilename, self.mode, encoding=self.encoding)
E   FileNotFoundError: [Errno 2] No such file or directory: 'C:\\Users\\86158\\Desktop\\UiHMTTAutoItem\\scripts\\log\\hmtt.log'</stack-trace>
      </failure>
      <attachments/>
      <labels/>
      <steps/>
    </test-case>
  </test-cases>
</ns0:test-suite>
